<?xml version="1.0" encoding="utf-8"?>
<!-- =================================================================================== -->
<!-- |    This document was autogenerated by xacro from robot.urdf.xacro               | -->
<!-- |    EDITING THIS FILE BY HAND IS NOT RECOMMENDED                                 | -->
<!-- =================================================================================== -->
<robot name="Uqtr_Robot">
  <!--<gazebo reference ="chassis">
     <material>Gazebo/Orange</material>
  </gazebo>-->
  <gazebo reference="roue_motrice_droite">
    <material>Gazebo/Black</material>
  </gazebo>
  <gazebo reference="roue_motrice_gauche">
    <material>Gazebo/Black</material>
  </gazebo>
  <gazebo reference="capteur_laser_avant">
    <material>Gazebo/Yellow</material>
  </gazebo>
  <gazebo reference="capteur_laser_arriere">
    <material>Gazebo/Yellow</material>
  </gazebo>
  <!-- capteur_laser_avant -->
  <gazebo reference="capteur_laser_avant">
    <turnGravityOff>false</turnGravityOff>
    <sensor name="chassis_hokuyo_sensor" type="ray">
      <pose>0 0 0 0 0 </pose>
      <visualize>false</visualize>
      <update_rate>20</update_rate>
      <!-- 20-->
      <ray>
        <scan>
          <horizontal>
            <samples>720</samples>
            <resolution>1</resolution>
            <min_angle>-2.35619449</min_angle>
            <max_angle>2.35619449</max_angle>
          </horizontal>
        </scan>
        <range>
          <min>0.10</min>
          <max>40.0</max>
          <resolution>0.1</resolution>
        </range>
        <noise>
          <type>gaussian</type>
          <mean>0.0</mean>
          <stddev>0.01</stddev>
        </noise>
      </ray>
      <plugin filename="libgazebo_ros_laser.so" name="gazebo_ros_head_hokuyo_controller">
        <topicName>/scan_avant</topicName>
        <frameName>capteur_laser_avant</frameName>
      </plugin>
    </sensor>
  </gazebo>
  <!-- capteur_laser_arriere-->
  <gazebo reference="capteur_laser_arriere">
    <turnGravityOff>false</turnGravityOff>
    <sensor name="chassis_hokuyo_sensor_arr" type="ray">
      <pose>0 0 0 0 0 </pose>
      <visualize>false</visualize>
      <update_rate>20</update_rate>
      <ray>
        <scan>
          <horizontal>
            <samples>720</samples>
            <resolution>1</resolution>
            <min_angle>-5.672320067</min_angle>
            <max_angle>-0.785398163</max_angle>
          </horizontal>
        </scan>
        <range>
          <min>0.10</min>
          <max>40.0</max>
          <resolution>0.001</resolution>
        </range>
        <noise>
          <type>gaussian</type>
          <mean>0.0</mean>
          <stddev>0.01</stddev>
        </noise>
      </ray>
      <plugin filename="libgazebo_ros_laser.so" name="gazebo_ros_head_hokuyo_controller">
        <topicName>/scan_arriere</topicName>
        <frameName>capteur_laser_arriere</frameName>
      </plugin>
    </sensor>
  </gazebo>
  <!-- IMU -->
  <gazebo>
    <plugin filename="libgazebo_ros_imu.so" name="imu_plugin">
      <alwaysOn>true</alwaysOn>
      <bodyName>adis1647x_pcb</bodyName>
      <topicName>imu</topicName>
      <serviceName>imu_service</serviceName>
      <gaussianNoise>0.0</gaussianNoise>
      <updateRate>20.0</updateRate>
    </plugin>
  </gazebo>
  <gazebo>
    <plugin filename="libgazebo_ros_diff_drive.so" name="differential_drive_controller">
      <alwaysOn>true</alwaysOn>
      <legacyMode>false</legacyMode>
      <updateRate>100</updateRate>
      <leftJoint>chassis_roue_motrice_gauche</leftJoint>
      <rightJoint>chassis_roue_motrice_droite</rightJoint>
      <wheelSeparation>0.6855600</wheelSeparation>
      <wheelDiameter>0.2032000</wheelDiameter>
      <torque>20</torque>
      <commandTopic>Uqtr_Robot/diff_drive_controller/cmd_vel</commandTopic>
      <odometryTopic>Uqtr_Robot/diff_drive_controller/odom</odometryTopic>
      <odometryFrame>odom</odometryFrame>
      <odometrySource>world</odometrySource>
      <publishOdomTF>false</publishOdomTF>
      <publishTf>1</publishTf>
      <rosDebugLevel>na</rosDebugLevel>
      <robotBaseFrame>base_link</robotBaseFrame>
      <publishWheelTF>true</publishWheelTF>
      <publishWheelJointState>false</publishWheelJointState>
    </plugin>
  </gazebo>
  <!--Gravite pour le chassis-->
  <gazebo reference="chassis">
    <turnGravityOff>false</turnGravityOff>
  </gazebo>
  <gazebo reference="roue_motrice_droite">
    <mu1 value="449"/>
    <!--449-->
    <mu2 value="449"/>
    <!--449-->
    <kp value="1000000.0"/>
    <!--10000000.0-->
    <kd value="1.0"/>
    <!--1.0-->
  </gazebo>
  <gazebo reference="roue_motrice_gauche">
    <mu1 value="449"/>
    <!--449-->
    <mu2 value="449"/>
    <!--449-->
    <kp value="1000000.0"/>
    <!--10000000.0-->
    <kd value="1.0"/>
    <!--1.0-->
  </gazebo>
  <gazebo reference="chassis">
    <mu1>0.0</mu1>
    <mu2>0.0</mu2>
  </gazebo>
  <!--Dummy-->
  <link name="base_link">
   </link>
  <joint name="dummy_joint" type="fixed">
    <origin rpy="0 0 0" xyz="0 0 0"/>
    <parent link="base_link"/>
    <child link="chassis"/>
  </joint>
  <!--Chassis-->
  <link name="chassis">
    <inertial>
      <mass value="49.497"/>
      <inertia ixx="1.07" ixy="0" ixz="0.09" iyy="4.55" iyz="0" izz="5.30"/>
    </inertial>
    <visual>
      <origin rpy="0 0 0" xyz="0 0 0"/>
      <geometry>
        <mesh filename="package://uqtr_robot/meshes/chassis.dae"/>
      </geometry>
    </visual>
    <collision>
      <origin rpy="0 0 0" xyz="0 0 0"/>
      <geometry>
        <mesh filename="package://uqtr_robot/meshes/chassis.dae"/>
      </geometry>
      <physics type="ode">
        <gravity xyz="0 0 -9.8"/>
        <ode>
          <solver dt="0.001" iters="10" sor="1.3" type="quick"/>
          <constraints cfm="0.0" contact_max_correcting_vel="10.0" contact_surface_layer="0.001" erp="0.1"/>
        </ode>
      </physics>
    </collision>
  </link>
  <!-- roue motrice droite -->
  <link name="roue_motrice_droite">
    <inertial>
      <mass value="1.3118"/>
      <inertia ixx="0.00367244758684" ixy="0.0" ixz="0.0" iyy="0.00367244758684" iyz="0.0" izz="0.006770567104"/>
    </inertial>
    <visual>
      <origin rpy="0 0 0" xyz="0 0 0"/>
      <geometry>
        <mesh filename="package://uqtr_robot/meshes/roue_motrice_droite.STL"/>
      </geometry>
      <material name="">
        <color rgba="0.29804 0.29804 0.29804 1"/>
      </material>
    </visual>
    <collision>
      <origin rpy="0 0 0" xyz="0 0 0"/>
      <geometry>
        <mesh filename="package://uqtr_robot/meshes/roue_motrice_droite.STL"/>
      </geometry>
    </collision>
  </link>
  <joint name="chassis_roue_motrice_droite" type="continuous">
    <origin rpy="0 0 0" xyz="0.074873 -0.34278 0.086706"/>
    <parent link="chassis"/>
    <child link="roue_motrice_droite"/>
    <axis xyz="0 1 0"/>
    <limit effort="100" velocity="100"/>
    <dynamics damping="0.0" friction="0.0"/>
  </joint>
  <!-- roue motrice gauche -->
  <link name="roue_motrice_gauche">
    <inertial>
      <mass value="1.3118"/>
      <inertia ixx="0.00367244758684" ixy="0.0" ixz="0.0" iyy="0.00367244758684" iyz="0.0" izz="0.006770567104"/>
    </inertial>
    <visual>
      <origin rpy="0 0 0" xyz="0 0 0"/>
      <geometry>
        <mesh filename="package://uqtr_robot/meshes/roue_motrice_gauche.STL"/>
      </geometry>
      <material name="">
        <color rgba="0.29804 0.29804 0.29804 1"/>
      </material>
    </visual>
    <collision>
      <origin rpy="0 0 0" xyz="0 0 0"/>
      <geometry>
        <mesh filename="package://uqtr_robot/meshes/roue_motrice_gauche.STL"/>
      </geometry>
    </collision>
  </link>
  <joint name="chassis_roue_motrice_gauche" type="continuous">
    <origin rpy="0 0 0" xyz="0.074873 0.34278 0.086706"/>
    <parent link="chassis"/>
    <child link="roue_motrice_gauche"/>
    <axis xyz="0 1 0"/>
    <limit effort="100" velocity="100"/>
    <dynamics damping="0.0" friction="0.0"/>
  </joint>
  <!-- capteur laser avant -->
  <link name="capteur_laser_avant">
    <inertial>
      <origin rpy="0 0 0" xyz="0.02471 6.5845E-10 -0.011912"/>
      <mass value="0.32341"/>
      <inertia ixx="1.9683E-05" ixy="6.844E-12" ixz="-0.00012644" iyy="0.00083192" iyz="1.0654E-12" izz="0.00081224"/>
    </inertial>
    <visual>
      <origin rpy="0 0 0" xyz="0 0 0"/>
      <geometry>
        <mesh filename="package://uqtr_robot/meshes/capteur_laser_avant.STL"/>
      </geometry>
      <material name="">
        <color rgba="0 0 0 1"/>
      </material>
    </visual>
    <collision>
      <origin rpy="0 0 0" xyz="0 0 0"/>
      <geometry>
        <mesh filename="package://uqtr_robot/meshes/capteur_laser_avant.STL"/>
      </geometry>
    </collision>
  </link>
  <joint name="chassis_capteur_laser_avant" type="fixed">
    <origin rpy="0 0 0" xyz="0.76419 0.351 0.28335"/>
    <parent link="chassis"/>
    <child link="capteur_laser_avant"/>
    <axis xyz="0 0 0"/>
  </joint>
  <!-- capteur laser arriere  -->
  <link name="capteur_laser_arriere">
    <inertial>
      <origin rpy="0 0 3.14" xyz="0.007429 -9.2927E-10 -0.016915"/>
      <mass value="0.22916"/>
      <inertia ixx="0" ixy="0" ixz="0" iyy="0" iyz="0" izz="0"/>
    </inertial>
    <visual>
      <origin rpy="0 0 0" xyz="0 0 0"/>
      <geometry>
        <mesh filename="package://uqtr_robot/meshes/capteur_laser_arriere.STL"/>
      </geometry>
      <material name="">
        <color rgba="0 0 0 1"/>
      </material>
    </visual>
    <collision>
      <origin rpy="0 0 0" xyz="0 0 0"/>
      <geometry>
        <mesh filename="package://uqtr_robot/meshes/capteur_laser_arriere.STL"/>
      </geometry>
    </collision>
  </link>
  <joint name="chassis_capteur_laser_arriere" type="fixed">
    <origin rpy="0 0 0" xyz="-0.76419 -0.351 0.28335"/>
    <parent link="chassis"/>
    <child link="capteur_laser_arriere"/>
    <axis xyz="0 0 0"/>
  </joint>
  <!-- adis1647x_pcb ** pas configurer encore ** -->
  <link name="adis1647x_pcb">
    <inertial>
      <origin rpy="0 0 0" xyz="3.3961E-18 3.8417E-18 0.005"/>
      <mass value="0.026795"/>
      <inertia ixx="0" ixy="0" ixz="0" iyy="0" iyz="0" izz="0"/>
    </inertial>
    <visual>
      <origin rpy="0 0 0" xyz="0 0 0"/>
      <geometry>
        <mesh filename="package://uqtr_robot/meshes/adis1647x_pcb.STL"/>
      </geometry>
      <material name="">
        <color rgba="0.89804 0.91765 0.92941 1"/>
      </material>
    </visual>
    <collision>
      <origin rpy="0 0 0" xyz="0 0 0"/>
      <geometry>
        <mesh filename="package://uqtr_robot/meshes/adis1647x_pcb.STL"/>
      </geometry>
    </collision>
  </link>
  <joint name="chassis_adis1647x_pcb" type="fixed">
    <origin rpy="0 0 0" xyz="0 0 0.00122"/>
    <parent link="chassis"/>
    <child link="adis1647x_pcb"/>
    <axis xyz="0 0 0"/>
  </joint>
</robot>
